Workbook
Name grade_level: 'Review 3- Final'!$D$9:$D$24
Name grade_table: References!$A$52:$D$56

Sheet Quy_trinh
A2: Hoạt động review đồ án giữa kỳ này được triển khai từ kỳ SU24
A3: Nhằm cải thiện chất lượng sản phẩm đồ án và phát hiện sớm các nhóm
A4: có vấn đề và hỗ trợ kịp thời
A6: Việc review sẽ được điều phối bởi hội đồng chuyên môn,
A7: Chủ nhiệm Bộ môn: Lê Thiện Nhật Quang (quangltn3@fe.edu.vn)
A9: Việc review được thực hiện vào tuần 4,8,12 của kỳ đồ án
A11: 1 tuần trước buổi review:
A12: - hội đồng thông báo thời hạn nộp sản phẩm và đánh giá
A13: - nhóm sinh viên nộp tài liệu tới thời điểm hiện tại,
A14: - mentor sử dụng template này và đánh giá ở cột mentor
A15: trong vòng 1 ngày sau buổi review
A16: - reviewer gửi lại comment, keep CC TBM và các cán bộ liên quan

Sheet Review 1
B1: FPTU SE Capstone Project- Review 1 Checklist
A3: Project Code: | B3: {code của nhóm, ví dụ: SE05}
A4: Project Name: | B4: {tên đồ án}
A5: Reviewer(s): | B5: {account người review vd longnx6; RinNV}
A6: Review date: | B6: {ngày thực hiện review}
B8: Question | C8: Priority | D8: Assessment | E8: Mentor Comment | F8: Reviewer Comment
B9: P1- Coverage of Objectives
B10: Is problem to solve stated clearly? | C10: Mandatory
B11: Is a functional overview of the system provided?
B12: If assumptions that affect implementation have been made, are they stated?
B13: Is size of system (Usecase Points) larged enough for members to do in project? | C13: Mandatory
B14: P2-Practical applicability
B15: Does project have real users with real problems (pain/gain points)?
B16: Does project team work with real stakeholders ?
B17: P3-Innovation and Creativity
B18: Does project introduce new business model or localize successful global business models?
B19: Does project apply new technologies,algorithms or UI/UX (AR,VR,voice interaction?
B20: D1-URD-SRS-Overview
B21: Do the requirements provide an adequate basis for design? | C21: Mandatory
B22: Is the implementation priority of each requirement included? | C22: Mandatory
B23: Are algorithms intrinsic to the use-case defined?
B24: Is any necessary information missing from a requirement? If so, is it identified as to-be-determined marker
B25: Does the team use workflow tools to model the system's business flow? | C25: Mandatory
B26: D1- Correctness
B27: Do any requirements conflict with or duplicate other requirements?
B28: Is each requirement verifiable (such as by review, testing, demonstration, or analysis)? | C28: Mandatory
B29: Is each requirement in scope for the project? | C29: Mandatory
B30: Can all of the requirements be implemented within known constraints? | C30: Mandatory
B31: D1- Quality attributes
B32: Are all performance objectives properly specified? | C32: Mandatory
B33: Are all security and safety considerations properly specified?
B34: Are other pertinent quality attribute goals explicitly documented and quantified, with the acceptable trade-offs specified?
B35: Check whether interfaces with other systems are described | C35: Mandatory
B36: Check whether the required hardware is described
B37: Check whether specific software requirements are documented
B38: Check whether networking Issues and connectivity requirements are documented
B39: Check whether specific communication requirements are documented
B40: Check whether availability requirements are documented
B41: D1- Special user requirements
B42: Multi Language support
...

Sheet Review 2
B1: FPTU SE Capstone Project- Review 2 Checklist
A3: Project Code: | B3: ='Review 1'!B3 -> {code của nhóm, ví dụ: SE05}
A4: Project Name: | B4: ='Review 1'!B4 -> {tên đồ án}
A5: Reviewer(s):
A6: Review date:
B8: Question | C8: Assessment | D8: Mentor Comment | E8: Reviewer Comment
B9: A. Software Product
B10: 1. Does the system architecture, including sub-systems and their interconnections, clearly documented in both deployment and process views?
B11: 2. Does the Entity-Relationship Diagram (ERD) accurately represent all entities, their relationships, and attributes within the system?
B12: 3. Are the main entity models comprehensive enough to encapsulate all required states and behaviors as illustrated in the state diagrams of key system entities?
B13: 4. Is the use of external services (such as third-party APIs) justified and implemented effectively within the project?
B14: 5. Is the source code structure organized in a manner that supports logical understanding, maintainability, and potential for future scalability?
B15: B. Project Management
B16: 1. Are tasks fairly and appropriately distributed among members considering their interests and skills?
B17: 2. Is there effective communication and collaboration among team members?
B18: 3. Does the team meet deadlines consistently?
B19: C. Interaction with Supervisor(s)
B20: 1. Are regular meetings with the Supervisor organized?
... B37: {mentor/reviewer có thể bổ sung comment ở mục này}

Sheet Review 3- Final
A1: FPTU SE Capstone Project- Review 3
A2: Project Code | B2: ='Review 1'!B3 -> {code của nhóm, ví dụ: SE05}
A3: Project Name | B3: ='Review 1'!B4 -> {tên đồ án}
A4: Reviewer(s)
A5: Review Date
A7: I. Criteria Evaluation
A8: Code | B8: Name | C8: Evaluation Criteria | D8: Grade Level | E8: Grade | F8: Mentor comment | G8: Reviewer Comment
A9: P1 | B9: Scope: Coverage of objectives | C9: - Problem to solve (innovation, creative, …) - Size of system: weighted number of business flows, weighted actor and usecase count. - Coverage of objectives - Completeness of requirements | E9: =IF(VLOOKUP(D9,grade_table,2,FALSE)>0,VLOOKUP(A9,Rubric!B2:H17,VLOOKUP(D9,grade_table,2,FALSE)+2,FALSE),"") -> #N/A
A10: P2 | B10: Practical applicability | C10: - Deployed in production mode for using with domains, real environtments, real data. - Have real users/customers - Have real problems: pain/gain points. - Working with real stakeholders. - Have investors invest for this project. - Product can be extend in futures. | E10: =IF(VLOOKUP(D10,grade_table,2,FALSE)>0,VLOOKUP(A10,Rubric!B3:H18,VLOOKUP(D10,grade_table,2,FALSE)+2,FALSE),"") -> #N/A
A11: P3 | B11: Innovation and Creativity | C11: - New business models/ Localize successful global business models - New UI/UX: interaction by voice,AR , VR, 3D modesl ... - New Techs: Drone, Flycam, Edge computing… - New algorithms: computer vision , deep learning … | E11: =IF(VLOOKUP(D11,grade_table,2,FALSE)>0,VLOOKUP(A11,Rubric!B4:H19,VLOOKUP(D11,grade_table,2,FALSE)+2,FALSE),"") -> #N/A
A12: P4 | B12: UI/UX | C12: - Branding: logo, icon , slogan - Layouts: use uniform elements and spacing. - Navigation: moving between screens of an app - Text usage: using text with correct meaning, language, without spelling mistakes, and right typography. - Color system: apply color to UI in a meaningful way | E12: =IF(VLOOKUP(D12,grade_table,2,FALSE)>0,VLOOKUP(A12,Rubric!B5:H20,VLOOKUP(D12,grade_table,2,FALSE)+2,FALSE),"") -> #N/A
A13: P5 | B13: Technology choices for Software Architecture | C13: - Reasonable use of external services (3rd services- API) - Using up- to- date Frontend technology with good design pattern (Angular,ReactJs, VueJs Jquery ,Typescript..) - Using up- to- date Backend technology with good design (RestApi, grpc, GraphQl ..) - Using up- to- date Mobile technology with good design | E13: =IF(VLOOKUP(D13,grade_table,2,FALSE)>0,VLOOKUP(A13,Rubric!B6:H21,VLOOKUP(D13,grade_table,2,FALSE)+2,FALSE),"") -> #N/A
A14: P6 | B14: Application of computing knowledge for Implementation | C14: - Apply and pass source code review tool (Ex: Sonar Cloud) to check: maintainability , reliability , code coverage , code duplication... - Understand and apply pattern for Front- end (Typescript, MVVM…) - Understand and apply pattern for Web/ Web API (MVC, 3- Layers) - Understand and apply pattern for Mobile App (MVVM, MVP..) - Understand and apply programming techniques: OOP, SOLID principles, using config file (connection string, access token), enumeration... | E14: =IF(VLOOKUP(D14,grade_table,2,FALSE)>0,VLOOKUP(A14,Rubric!B7:H22,VLOOKUP(D14,grade_table,2,FALSE)+2,FALSE),"") -> #N/A
A15: P7 | B15: Complexity of algorithm/ internal processing | C15: - Correctly state the problem to be solved - Choose the right algorithm to solve the problem - Use the right libraries / source code / services available to solve the problem - Implement and enhance existing solutions for better result. - Find a new way to solve the problem | E15: =IF(VLOOKUP(D15,grade_table,2,FALSE)>0,VLOOKUP(A15,Rubric!B8:H23,VLOOKUP(D15,grade_table,2,FALSE)+2,FALSE),"") -> #N/A
A16: P8 | B16: Technology choices for Deployment & Maintenance | C16: - Use git repository for source code storage with suitable branching model - Apply and have evidence of Continous Integration (CI) - Apply and have evidence of Continous Delivery - Deploy on cloud computing with automation pipelines - Apply system monitoring and centrallized system logging | E16: =IF(VLOOKUP(D16,grade_table,2,FALSE)>0,VLOOKUP(A16,Rubric!B9:H24,VLOOKUP(D16,grade_table,2,FALSE)+2,FALSE),"") -> #N/A
A17: D1 | B17: User requirement and System Requirment | C17: - User requirements: context, problems, proposed solutions.. - System functional requirements: usecase overview usecase specification - System nonfunctional requirements: quality attributes (performance, security, safety.. ), environtment (hardware, software, network, communication..) - Document: format, layout, grammar, spelling and punctuation. - Diagram: usecase diagram (actor, usecase , relationships ...), sequence diagram , activity diagram | E17: =IF(VLOOKUP(D17,grade_table,2,FALSE)>0,VLOOKUP(A17,Rubric!B10:H25,VLOOKUP(D17,grade_table,2,FALSE)+2,FALSE),"") -> #N/A
A18: D2 | B18: Architecture Design Document | C18: - Strategy for: technology and 3rd services selection, quality attribues of system (performance- security- data storage...), deployment environment - System architecture: sub- systems and connection between theme in deployment view, process view. - Component design (physical view) for sub- system: component boundaries well defined, including functionality and interfaces - Package design (logical view) for sub- system - Data design: data structure , data flow | E18: =IF(VLOOKUP(D18,grade_table,2,FALSE)>0,VLOOKUP(A18,Rubric!B11:H26,VLOOKUP(D18,grade_table,2,FALSE)+2,FALSE),"") -> #N/A
A19: D3 | B19: Detail Design Document | C19: - Class design: design for each unit contain appropriate views (e.g., static structure, data definition, data flow, control flow, states, etc.), has the overall function and intent of each unit - Database Design: normalized, mapping with logical design , tables, fields , size and type of fields, default values.. - Logical Design (ERD): entity , entity relationship, attributes of entity . - Screen design: Screen(id, name, description),Component in screen (type, required , format ..), Screen flows (screen structure and transition between screens) | E19: =IF(VLOOKUP(D19,grade_table,2,FALSE)>0,VLOOKUP(A19,Rubric!B12:H27,VLOOKUP(D19,grade_table,2,FALSE)+2,FALSE),"") -> #N/A
A20: D4 | B20: Testing Document | C20: - Test plan: product to be tested, the definition of scope of testing (unit test, integration test, system test, user acceptance test), test type (black box, white box ), test deliverables. - Test case specification: test conditions, test suites, test cases in test suites, detailed information of test cases(test procedures, input data, expected output, constraints..) - Test report: testing objectives, activities, results (number of designed, implemented, executed, and succeeded test cases..), conclusion about the quality of software product. | E20: =IF(VLOOKUP(D20,grade_table,2,FALSE)>0,VLOOKUP(A20,Rubric!B13:H28,VLOOKUP(D20,grade_table,2,FALSE)+2,FALSE),"") -> #N/A
A21: D5 | B21: System Deployment and Delivery Package | C21: - Delivery package: documents , software, source code, installation guide. - Installabilty: check with the delivery package, other people can install system and run as a demonstration in front of the committee. - Script database, data inside the database. - Training images of computer vision algorithm. - Devices and other resources are supplied for the project. - Acceptance notes from customers for the project from external (if required) | E21: =IF(VLOOKUP(D21,grade_table,2,FALSE)>0,VLOOKUP(A21,Rubric!B13:H28,VLOOKUP(D21,grade_table,2,FALSE)+2,FALSE),"") -> #N/A
A22: AI
A26: II. Evalutaion
A27: Grade Level | B27: Count | C27: Suggestion for Project Supervisor | D27: Check | E27: Reviewer(s) Comment
A28: Excellent | B28: =COUNTIF(grade_level,A28) -> 0 | E28: Reviewer đưa ra đề xuất chung cho toàn dự án đến với GVHD và team. Các đề xuất này mang tính tham khảo, quyết định cuối cùng về việc nhóm đồ án có được bảo vệ hay không sẽ thuộc về GVHD.
A29: Good | B29: =COUNTIF(grade_level,A29) -> 0
A30: Acceptable | B30: =COUNTIF(grade_level,A30) -> 0
A31: Fail | B31: =COUNTIF(grade_level,A31) -> 0
A32: N/A | B32: =COUNTIF(grade_level,A32) -> 0

Sheet Rubric
A1: Component | B1: Code | C1: Criteria | D1: Excellent 8- 10 | E1: Good 6- 8 | F1: Acceptable 4- 6 | G1: Fail 0- 4 | H1: Evaluation Criteria
A2: Product | B2: P1 | C2: =VLOOKUP(B2,_xlnm.Criteria,2,FALSE) -> #NAME? | D2: All of the objectives have been addressed, with few cases that may be questionable and/or additional aspects explored | E2: The objectives have been met, at least in part but clearly not in entirety and/or there are some clear deficiencies or aspects that fall short | F2: Key objectives are generally met with significant deficiencies and/or shortcomings, but some important features are missing or inadequately implemented | G2: Very little if any of the objectives appear to be met in any clear way | H2: - Problem to solve (innovation, creative, …) - Size of system :weighted number of business flows, weighted actor and usecase count. - Coverage of objectives - Completenese of requirements
B3: P2 | C3: =VLOOKUP(B3,_xlnm.Criteria,2,FALSE) -> #NAME? | D3: The capstone project's product can be a real product or already a product with a large enough user base. | E3: The capstone project's product can be a real product with some improvement. | F3: The capstone project's product can be a product for a small size of users group with basic functions. | G3: The capstone project's product cannot be used for real users. | H3: - Have real users/customers - Have real problems: pain/gain points. - Working with real stakeholders. - Deployed in production mode for using with domains, real environtments,real data. - Product can be extend in futures. - Have investors invest for this project.
B4: P3 | C4: =VLOOKUP(B4,_xlnm.Criteria,2,FALSE) -> #NAME? | D4: The approach to the problem statement chosen is innovative and meets the objective of the project effectively. | E4: Understanding the purpose driving the process of innovation (Who needs this? Why?) Create a product with a innovation approach and provide an optimized way to use the product. | F4: Understanding the basic purpose of innovation in the project but does not thoroughly consider the needs and interests of target users. | G4: Just follow "directions" without understanding the purpose of innovation in the project. Use only typical sources of information and does not offer new ideas. | H4: - New business models/ Localize successful global business models - New UI/UX: interaction by voice,AR , VR, 3D modesl ... - New Techs : Drone, Flycame, Edge computing… - New algorithms: computer vision , deep learning …
B5: P4 | C5: =VLOOKUP(B5,_xlnm.Criteria,2,FALSE) -> #NAME? | D5: Generally easy to use, very few unexpected outcomes | E5: Can be used with some effort, outcomes are as expected in most cases but there are some aspects that are confusing and/or need more effort than warranted | F5: The software's user interface is usable but at times difficult to comprehend, there are aspects of the software that are user unfriendly and/or illogical | G5: Very little to any of the software is intuitive to use, there are little or no instructions, excessive effort is required to make use of the software | H5: - Branding : logo, icon , slogan - Layouts: use uniform elements and spacing. - Navigation: moving between screens of an app - Text usage: using text with correct meaning, language, without spelling mistakes, and right typography. - Color system: apply color to UI in a meaningful way
B6: P5 | C6: =VLOOKUP(B6,_xlnm.Criteria,2,FALSE) -> #NAME? | D6: Excellent choices of technology and clearly established ability to use them with few if any caveats | E6: Reasonable choices of technology but lacking in the capacity to integrate/make use of them, perhaps some choices could have been better in hindsight | F6: Justifiable choices of technology but lacking in the capacity to integrate/make use of them, perhaps some choices could have been better in hindsight | G6: no or little ability to make use of appropriate third party libraries or systems, inappropriate/ill- suited choices of technology | H6: - Reasonable use of external services (3rd services- API) - Using up- to- date Frontend technology with good design pattern (Angular,ReactJs, VueJs Jquery ,Typescript..) - Using up- to- date Backend technology with good design (RestApi, grpc, GraphQl ..) - Using up- to- date Mobile technology with good design
B7: P6 | C7: =VLOOKUP(B7,_xlnm.Criteria,2,FALSE) -> #NAME? | D7: a high standard of coding and commenting is evident, the code is easy to read and appears clear to maintain, ready to be open sourced | E7: reasonable clarity and code can be followed with some effort, comments help to understand the code, logical organization may be lacking in some ways and there may be a number of questionable expressions | F7: Code for run only. Team doesn't care about code quality : maintainablity , security , resusability. Doesn't apply any detail design pattern in source code. Duplication code , deadcode still exists in source code. | G7: Extremely hard to read, little or no attention to code formatting, lack of logical organization, little or no appreciation of coding and commenting practices | H7: - Apply and pass source code review tool (Ex: Sonar Cloud) to check : maintainability , reliability , code coverage , code duplication... - Understand and apply pattern for Front- end (Typescript, MVVM…) - Understand and apply pattern for Web/ Web API (MVC, 3- Layers) - Understand and apply pattern for Mobile App (MVVM, MVP..) - Understand and apply programming techniques: OOP, SOLID principles, using config file (connection string, access token), enumeration...
B8: P7 | C8: =VLOOKUP(B8,_xlnm.Criteria,2,FALSE) -> #NAME? | D8: Can apply computer science knowledge when and where appropriate showing sophistication, a high level of appreciation for programming intricacies | E8: a reasonable demonstration of computer science knowledge in terms of data structures, algorithms and other applicable theory, but largely piecemeal without sophistication | F8: showing a good grasp and reasonable ability to apply computer science knowledge to solve the problem in question, but there are some noticeable limitations that need to work on | G8: no or little demonstration of anything other than basic programming skills, frequent use of superfluous and inappropriate programming approaches | H8: - Correctly state the problem to be solved - Choose the right algorithm to solve the problem - Use the right libraries / source code / services available to solve the problem - Implement and enhance existing solutions for better result. - Find a new way to solve the problem
B9: P8 | C9: =VLOOKUP(B9,_xlnm.Criteria,2,FALSE) -> #NAME? | D9: Straight forward and easy to build and install, little or no effort required (works out of the box) | E9: Can be built and installed with some effort, problems occurred but can be overcome with minor changes or clarifications to instructions | F9: Take more effort to build and install the products. Too many manual and time- consuming tasks. | G9: very difficult or impossible to build without modifications, frequent build problems, little or no instructions and more or less unable to install in any reasonable way | H9: - Use git repository for source code storage with suitable branching model - Apply and have evidence of Continous Integration (CI) - Apply and have evidence of Continous Delivery - Deploy on cloud computing with automation pipelines - Apply system monitoring and centrallized system logging
A10: Document | B10: D1 | C10: =VLOOKUP(B10,_xlnm.Criteria,2,FALSE) -> #NAME? | D10: - Requirements are grouped logically - Requirements are described in sufficient detail and completeness - Requirements are stated precisely - Diagrams are simple and follow standard notation (UML) - Full references and no Plagiarism | E10: - Requirements are grouped generally logically, some important requirements are missing and described incorrectly. - Requirements are described in generally detail and completeness - Requirements are stated precisely in most cases. - Diagrams are simple and follow standard notation (UML) but have some drawing mistakes. - Have references but some references are missing and no plagiarism | F10: - Requirements are reasonable but a little bit incoherent grouped. - Requiremenst are described in structured format but not detail and not completeness. - Missing some important diagram, some diagrams are too complex and are not follow standard notation. - Have very little references and no plagiarism | G10: - Requirements are not grouped logically. - Insufficient content, document structure is not logical, flawed English with a lot of grammar, spelling, punctuation mistakes - Diagrams are too complex and are not follow standard notation. - No references - Plagiarism | H10: - User requirements: context, problems, proposed solutions.. - System functional requirements: usecase overview usecase specification - System nonfunctional requirements: quality attributes (performance, security, safety.. ), environtment (hardware, software, network, communication..) - Document : format, layout, grammar, spelling and punctuation. - Diagram : usecase diagram (actor, usecase , relationships ...), sequence diagram , activity diagram
B11: D2 | C11: =VLOOKUP(B11,_xlnm.Criteria,2,FALSE) -> #NAME? | D11: - Compelling design solution showing highly original creative development of concept, innovative application of techniques and exemplary use of principles . - Solution shows rigorous creative inquiry and investigation throughout design process with highly successful results. | E11: - Interesting design solution showing consistently creative development of concept, original development of technique and original application of principles. - Solution shows ongoing creative inquiry and exploration of design potential with largely effective results. | F11: Fundamentally sound design solution with moderately creative use of concept, fundamentally appropriate technique, and adequate application of principles. Solution shows some effort to challenge creative boundaries with limited or uneven success. | G11: - Does not attempt or is unable to complete design solutions. - Unsuccessful design solution due to lack of creative use of concept, limited exploration of technique and/or application of principles. - Little effort to challenge creative boundaries resulting in obvious or poorly developed solution. | H11: - Strategy for:technology and 3rd services selection, quality attribues of system (performance - security- data storage...), deployment environment - System architecture : sub- systems and connection between theme in deployment view, process view. - Component design (physical view) for sub- system : component boundaries well defined, including functionality and interfaces - Package design (logical view) for sub- system - Data design: data structure , data flow
B12: D3 | C12: =VLOOKUP(B12,_xlnm.Criteria,2,FALSE) -> #NAME? | D12: - Design has sufficient detail for someone else to develop the code. - Each unit have a unique identifier and follow style and naming convention - Design for each unit contains appropriate views (e.g., static structure, data definition, data flow, control flow, states, etc.) | E12: - Design has enough information for someone else to develop the code. - Each unit has a unique identifier and follows style and naming convention, but has some mistakes. - Design for each unit contains only important views (e.g., static structure, data definition, data flow, control flow, states, etc.) | F12: - Need a little effort for someone else to develop the code. - Unit design have mistakes in naming convention, the iconsisten style in many modules. - Design for each unit missing some important views | G12: - Someone else cannot develop the code with the design. - Too many mistakes in unit design - Design for each unit have single views only | H12: - Class design : design for each unit contain appropriate views (e.g., static structure, data definition, data flow, control flow, states, etc.), has the overall function and intent of each unit - Logical Design (ERD):entity , entity relationship, attributes of entity . - Database Design : normalized, mapping with logical design , tables, fields , size and type of fields, default values.. - Screen design : Screen(id, name, description),Component in screen (type, required , format ..), Screen flows (screen structure and transition between screens)
B13: D4 | C13: =VLOOKUP(B13,_xlnm.Criteria,2,FALSE) -> #NAME? | D13: - Test plan state clearly the type of test being implemented, the test objectives and how team will conduct the test. - Test case have group logically in test suites. Each test case in test suite have detail information for tester can follow and do the test execution without any support. - Test report organized summary of testing objectives, activities, and results. Report show understand product quality and decide whether a is on track for release. | E13: - Test plan state generally the type of test being implemented, the test objectives, and how the team will conduct the test. - Test cases have group logically in test suites but have some missing and inconsistent int test case detailed - Test report does not have enough information about product quality. | F13: - Have a test plan but need the effort to make clear information about how the team will conduct the test. - Test case doesn't group logically, test case detailed doesn't straightforward understand by the tester for doing test execution. - Test report lack of some important information about test activities and test result. | G13: - Does not have a test plan. - Test cases have a little with too many mistakes and missing detailed information. A tester cannot follow the test case specification to do the test. - Test report doesn't show the summary of testing activities and quality of the software product. | H13: - Test plan: product to be tested, the definition of scope of testing (unit test, integration test, system test, user acceptance test), test type (black box, white box ), test deliverables. - Test case specification: test conditions, test suites, test cases in test suites, detailed information of test cases(test procedures, input data, expected output, constraints..) - Test report: testing objectives, activities, results (number of designed, implemented, executed, and succeeded test cases..), conclusion about the quality of software product.
B14: D5 | C14: =VLOOKUP(B14,_xlnm.Criteria,2,FALSE) -> #NAME? | D14: - Software package and documents are grouped in correct structure folders and naming convention. - Document, slides, software packages, sourcode... and all related documents have been included in delivery package and all are the final versions. - Installation guides and environment configuration are described in detailed and easy to setup - Include script and code for automation deploy (e.g deployment as a code model). | E14: - Software package and documents are grouped in correct structure folders. - Some files in delivery package are not up- to- date version. - Installation guides and environment configuration are described in detailed and can be setup by someone but take a little time to finish. - Apply semi- automation deploy (e.g deployment as a code model), some modules can be deploy automatically. | F14: - Software package and documents are grouped , but some folders are not followed the structure format. - Some important files (SRS, ADD, Souce code, software package ... ) are not the final versions. - Installation guides and environment configuration are described in generalled and difficult for someone can setup. - Do not have automation deploy, all things are manually deployed. | G14: - Missing important file. - Too many files not following standard naming convention. - All documents are not up- to- date versions and there are too many different between the delivered version with the final version. - Do not have installation guide or the installation guide are not effective, someone can not follow the step to deploy system | H14: - Delivery package: documents , software, source code, installation guide. - Installabilty: check with the delivery package, other people can install system and run as a demonstration in front of the committee. - Script database, data inside the database. - Training images of computer vision algorithm. - Devices and other resources are supplied for the project. - Acceptance notes from customers for the project from external (if required)
A15: Presentation | B15: PE1 | C15: =VLOOKUP(B15,_xlnm.Criteria,2,FALSE) -> #NAME? | D15: Slides: well designed and very informative Team: presenting responsibilities are divided evenly among team members, voices are clear, the presentation is concise and easy to follow. Time management: finished on time, time is wisely distributed among the presentation sections. | E15: Slides: are well designed and provide most of needed information, there may be some mistakes in the slides but non is serious Team presents well but fail to focus on the key points to make the presentation more Time: used up all alotted time with less than 3 minutes to spare, however time could be distributed better among sections in hindsight. | F15: Slides provide enough information but contain errors and typos and are not well structured Team: presenters are verbose but not effective, coordination between team member need improvements. Time:finished 5- 10 minutes early or 5 minutes late, rushed at the end of the presentation | G15: Slides are incoherent, and either too long or too short Team: one or two members do most of the talking, voices are unclear and hard to understand, lacking of self- confidence. Time: finished with more than 15 minutes left, or more than 10 minutes over time | H15: - Design , content, illustration image and animation of presentation slides. - Team: presenting responsibilities , voices , flow of presentation, apprearance (uniform, T- shirt, nameplate...) - Time handling
B16: PE2 | C16: =VLOOKUP(B16,_xlnm.Criteria,2,FALSE) -> #NAME? | D16: Demonstrated all the main flows of the software in a clear, logical and realistic waythe team was full of confidence, most scenarios and possible issues have been thought out in advance to avoid unpleasant surprise | E16: Demonstrated most ofthe main flows of the software with some hiccups along the way, the demo went reasonaly well, but works need to be done to improve the clarity and effectiveness | F16: was able to demonstrate the main flows of the software but not without interruptions and retries, there were unexpected errors here and there, making the demonstration a bumpy ride | G16: the team was ill prepared, there were a host of problems that prevented the software from running as it should, making team fail to demonstrate most of the key features of the software | H16: - Quantity of main flows in demostration. - Quality of main flows: contextual , continous, visible results. - Data using for demonstration: meaningful, enough quantity, realistic. - Explanation for the demonstration - Mistake of person, exception of software system , failure of system during the demonstration
B17: PE3 | C17: =VLOOKUP(B17,_xlnm.Criteria,2,FALSE) -> #NAME? | D17: The team answers all question concisely with spot- on clarity | E17: The team was able to answer most questions correctly, but at times verbosely and unclearly. | F17: The team was able to answer the questions with some success, but the answers usually lack depth and are not spot- on, sometimes show misunderstanding or misconception | G17: The team failed to give acceptable answer to most questions | H17: - Level of understanding of questions. - Detail and completeness of the answers to the questions - Rate of correct questions - Member's assignment in answering questions
A18: AI | B18: AI1 | D18: In-depth data analysis; AI adds significant scientific or practical value; problem definition with strong contribution. | E18: Clearly analyzed why AI is needed; compared with traditional methods; considered scalability and practical applicability. | F18: Identified a problem suitable for AI; clearly described AI problem and objectives. | G18: Selecting problems not suitable for AI; forced application; unclear AI objectives. | H18: 1. Appropriateness of AI problem selection
B19: AI2 | D19: Applied advanced techniques (augmentation, ensemble, transfer learning...); optimized tuning; deep result analysis. | E19: Completed full data processing, training, parameter tuning; multi-criteria model evaluation; error analysis included. | F19: Prepared appropriate training data; selected suitable models; basic evaluation with standard metrics. | G19: Only using pre-built models without understanding; poor training data; no evaluation of model accuracy. | H19: 2. Quality of AI model building and training
B20: AI3 | D20: Built MLOps pipeline for automated training, testing, deployment; ensured scalability and long-term monitoring. | E20: AI fully integrated as system component; version control, update plan, maintenance considered. | F20: AI model integrated into system with API or interface; initial deployment process described. | G20: AI model operates independently, hard to integrate; no update or deployment process. | H20: 3. AI integration into software system

Sheet Rubric-AI-vi
A1: Câu hỏi | B1: Excellent 8- 10 | C1: Good 6- 8 | D1: Acceptable 4- 6 | E1: Fail 0- 4
A2: 1. Mức độ lựa chọn và xác định vấn đề AI | B2: Phân tích sâu đặc trưng dữ liệu, lợi ích AI mang lại, đề bài có đóng góp giá trị khoa học hoặc thực tiễn cao. | C2: Phân tích rõ lý do cần AI, so sánh với các giải pháp truyền thống, có cân nhắc khả năng mở rộng và thực tiễn. | D2: Xác định được bài toán phù hợp để ứng dụng AI, có mô tả rõ mục tiêu cần giải quyết. | E2: Chọn bài toán không phù hợp với AI, áp dụng AI khiên cưỡng, không có ý nghĩa thực tế. Mục tiêu AI mơ hồ.
A3: 2. Chất lượng xây dựng và huấn luyện mô hình AI | B3: Áp dụng kỹ thuật nâng cao (augmentation, ensemble, transfer learning...); tinh chỉnh tối ưu; phân tích chuyên sâu kết quả. | C3: Thực hiện đầy đủ quy trình xử lý dữ liệu, huấn luyện, tinh chỉnh; đánh giá chất lượng đa tiêu chí; có phân tích sai sót. | D3: Có chuẩn bị dữ liệu huấn luyện phù hợp; chọn mô hình hợp lý; đánh giá cơ bản với các chỉ số chất lượng. | E3: Chỉ dùng mô hình có sẵn, thiếu hiểu biết; dữ liệu sơ sài; không đánh giá độ chính xác mô hình.
A4: 3. Tích hợp AI vào hệ thống phần mềm | B4: Xây dựng pipeline tự động hóa (MLOps): huấn luyện, kiểm thử, triển khai; đảm bảo mở rộng và giám sát chất lượng mô hình lâu dài. | C4: Tích hợp AI thành phần chính thức trong hệ thống; có quy trình cập nhật, quản lý version, kế hoạch bảo trì. | D4: Mô hình AI đã được tích hợp vào hệ thống, có API hoặc giao diện sử dụng; có mô tả quy trình triển khai ban đầu. | E4: Mô hình AI hoạt động rời rạc, khó tích hợp; không có quy trình cập nhật, triển khai.

Sheet References
A3: No | B3: Code | C3: Project Type | D3: Product | E3: Document | F3: Presentation | G3: Column
A4: 1 | B4: APP | C4: Application Focus | D4: 0.5 | E4: 0.3 | F4: 0.2 | G4: 3
A5: 2 | B5: REA | C5: Research Focus | D5: 0.4 | E5: 0.4 | F5: 0.2 | G5: 5
A6: 3 | B6: STA | C6: Startup (TBA) | D6: 0.55 | E6: 0.25 | F6: 0.2 | G6: 7
A7: 4 | B7: SU21 | C7: Summer 2021 | D7: 0.6 | E7: 0.3 | F7: 0.1 | G7: 9
A9: I. Criteria table for evaluation project
D10: Application | F10: R&D | H10: Startup | J10: SU21
A11: Components | B11: Code | C11: Criteria Name | D11: Rate | E11: Mandatory | F11: Rate | G11: Mandatory | H11: Rate | I11: Mandatory | J11: Rate | K11: Mandatory
A12: Product | B12: P1 | C12: Scope: Coverage of objectives | D12: 0.25 | E12: Y | F12: 0.2 | G12: Y | H12: 0.2 | I12: Y | J12: 0.4 | K12: Y
B13: P2 | C13: Practical applicability | D13: 0.15 | E13: N | F13: 0.1 | G13: N | H13: 0.15 | I13: Y | J13: 0.05 | K13: N
B14: P3 | C14: Innovation and Creativity | D14: 0.1 | E14: N | F14: 0.1 | G14: N | H14: 0.15 | I14: N | J14: 0.05 | K14: N
B15: P4 | C15: UI/UX | D15: 0.15 | E15: Y | F15: 0.1 | G15: Y | H15: 0.15 | I15: Y | J15: 0.15 | K15: Y
B16: P5 | C16: Technology choices for Software Architecture | D16: 0.1 | E16: N | F16: 0.1 | G16: N | H16: 0.1 | I16: N | J16: 0.1 | K16: N
B17: P6 | C17: Application of computing knowledge for Implementation | D17: 0.1 | E17: Y | F17: 0.15 | G17: Y | H17: 0.1 | I17: Y | J17: 0.1 | K17: Y
B18: P7 | C18: Complexity of algorithm/ internal processing | D18: 0.1 | E18: N | F18: 0.2 | G18: Y | H18: 0.05 | I18: N | J18: 0.1 | K18: N
B19: P8 | C19: Technology choices for Deployment & Maintenance | D19: 0.05 | E19: N | F19: 0.05 | G19: N | H19: 0.1 | I19: N | J19: 0.05 | K19: N
A20: Document | B20: D1 | C20: User requirement and System Requirment | D20: 0.3 | E20: Y | F20: 0.2 | G20: Y | H20: 0.3 | I20: Y | J20: 0.4 | K20: Y
B21: D2 | C21: Architecture Design Document | D21: 0.15 | E21: N | F21: 0.15 | G21: N | H21: 0.15 | I21: N | J21: 0.15 | K21: N
B22: D3 | C22: Detail Design Document | D22: 0.3 | E22: Y | F22: 0.4 | G22: Y | H22: 0.25 | I22: Y | J22: 0.3 | K22: Y
B23: D4 | C23: Testing Document | D23: 0.15 | E23: N | F23: 0.15 | G23: N | H23: 0.15 | I23: N | J23: 0.1 | K23: N
B24: D5 | C24: System Deployment and Delivery Package | D24: 0.1 | E24: N | F24: 0.1 | G24: N | H24: 0.15 | I24: N | J24: 0.05 | K24: N
A25: Presentation | B25: PE1 | C25: Slides quality & presentation style & Time management | D25: 0.2 | E25: N | F25: 0.2 | G25: N | H25: 0.2 | I25: N | J25: 0.2 | K25: N
B26: PE2 | C26: Software product demonstration | D26: 0.5 | E26: Y | F26: 0.5 | G26: Y | H26: 0.5 | I26: Y | J26: 0.5 | K26: Y
B27: PE3 | C27: Inquiry Handling style | D27: 0.3 | E27: Y | F27: 0.3 | G27: Y | H27: 0.3 | I27: Y | J27: 0.3 | K27: Y
A31: II. Contribution Table
A32: No | B32: Code | C32: Name | D32: Rate
A33: 1 | B33: CR1 | C33: Contribution Rate reported by team | D33: 0
A34: 2 | B34: CR2 | C34: Contribution Rate reported by supervisor | D34: 0
A35: 3 | B35: CR3 | C35: Contribution Rate evaluated by Committee | D35: 1
A38: III. Project fail criteria
A39: 1. Final score is <4 | D39: OR | G39: Thiếu thành viên
A40: 2. Average score of each component (Product/Document/Presentation ) is < 4 | D40: OR
A41: 3. One of the mandatory criteria in each component is < 4 | D41: OR
A43: IV. Student fail criteria
A44: 1. Project team fail | D44: OR
A45: 2. Average score of student is < 4
A46: 3. Cannot handle any question
A47: 4. Contribution under 20% (4 members), 16% (5 members)
A49: V. Grade level
A51: Grade | B51: Index | C51: Min Point | D51: Max Point
...

Sheet Record_of_change
